Workbook
Name ActualPeriod: IF(AND(PrjSch!$X1<>"",PrjSch!$Y1<>""),PrjSch!$Y1-PrjSch!$X1+1,0)
Name Grade: PrjSch!$B$48:$B$51
Name LukUp_Efforts: '@LeadT_Setting'!$CZ$8:$DG$13
Name Mfg_DelayCode: '@LeadT_Setting'!$DS$6:$DS$29
Name Mfg_LOC: '@LeadT_Setting'!$AM$6:$AM$9
Name NS_HW: '@LeadT_Setting'!$AJ$16
Name NS_MF: '@LeadT_Setting'!$AL$16
Name NS_SW: '@LeadT_Setting'!$AK$16
Name PackgingType: '@LeadT_Setting'!$AM$12:$AM$20
Name PanelTyp: PrjSch!$C$18:$C$24
Name Payment_Status: '@LeadT_Setting'!$AL$6:$AL$10
Name PlanPeriod: PrjSch!$W1-PrjSch!$V1+1
Name ActualPeriod: IF(AND([1]PrjSch!$X1<>"",[1]PrjSch!$Y1<>""),[1]PrjSch!$Y1-[1]PrjSch!$X1+1,0)
Name Mfg_LOC: '[1]@LeadT_Setting'!$Y$6:$Y$9
Name NS_HW: '[1]@LeadT_Setting'!$V$16
Name NS_MF: '[1]@LeadT_Setting'!$X$16
Name NS_SW: '[1]@LeadT_Setting'!$W$16
Name PlanPeriod: [1]PrjSch!$W1-[1]PrjSch!$V1+1

Sheet VersionControl
A1: Document Name | C1: Mfg Scheduling Template | F1: Running Version | H1: ="V " & INDEX(A5:A25,COUNTA(A5:A25))
A3: Revision Control
A4: Rev No | B4: Rev Date | C4: Revision Reason
A5: 0 | B5: 45779 | C5: Developing the SWE schedule sheet. Identifying and listing activities. Working on Lead Times according to SWE activities/KPI. Discussing on SWE activities to analyse the suitabel KPI and visualizing execution workflow. Working on Layout of SWE Schedule for required information and fields. Discussing on SWE activities to analyse the suitabel KPI and visualizing execution workflow.In depth analysis on workflow in SWE environment and usability approach to link with cross-functional function. Inclusion of other fields to further improve the contents with respect to entry or no-entry of information in the schedule.
A6: 2.0 | B6: 45803 | C6: Version with improvement as user informed observations for functionalities. Integrationr ready to generate automatically from PM.
A7: 2.1 | B7: 45824 | C7: Addition of SWE Comm efforts, Correction of SWE Stage
A8: 2.2 | B8: 45825 | C8: Showing value error at some places in schedule, corrected the same. Installation, Pre-commissioning and Commissioning Lead time linked to PM Editables.
A9: 2.3 | B9: 45831 | C9: Correction of percent update basis on efforts only.

Sheet ReadMe
A1: Document Name | C1: =VersionControl!C1 | F1: Running Version | H1: =VersionControl!H1
A3: Guidelines for use
A4: SrNo | B4: Function | C4: Guidelines
A5: 1 | B5: SWE | C5: Buffertime is normally to be kept '0'. Required only in rare cases where more time available and some customer milestones need to be synched.
A6: 2 | B6: SWE | C6: Mismatch in "Customer Dates" & "PM Dates" is highlighted by red text. This needs to be resolved so that there is no RED, or comment should have clear solution.
A7: 3 | B7: SWE | C7: For each applicable efforts on KPI, the applicable non-zero value is to be entered. '0' or ' ' value in efforts column will affect status in dashboard
A8: 4 | B8: SWE | C8: LD fields to be filled carefully. There are 4 fields namely, LD Date, LD max/wk, LD max of OV, LD remarks
A9: 5 | B9: SWE | C9: The LD max/wk is the max value when multiple LD terms exists based on milestone delivery period
A10: 6 | B10: SWE | C10: The warranty terms are to be written in detail as mentioned in PO.
A11: 7 | B11: SWE | C11: The scope definition is done at scope area.
A12: 8 | B12: SWE | C12: User to enter the actual dates and % completion as per activity completion. The necessary warning & alarms are configured to get wake up call.
A13: 9 | B13: SWE | C13: For each stuck KPI, the provision is made to identify the stake holder who can help to progress the KPI. User to select correct from the list. The list contents Engineering (Lite RED) ,Purchase (Orange) ,Software (Lit Blue),Project Management (Blue),Manufacturing (Brown),Sales (Cyan),Client (Purple).
A14: 10 | B14: SWE | C14: User can enter suitable remark in the remark column. Essentially, the remark areas is scribble area that can be utilised to generate reminders or list of to do or store historical information for user to refere in later time
A15: 11
A16: 12
A17: 13
A18: 14
A19: 15
A20: 16
A21: 17
A22: 18
A23: 19
A24: 20
A25: 21
A26: 22
... A49: 45

Sheet PrjSch
B1: Guidelines | C1: *OR No. | D1: FSL/2122/CEN/OR002 | L1: Doc Name & Ver. | N1: Trial Release V2.0 | W1: Start Date | AB1: Days in SWE | AE1: LD Date | CO1: Today | DE1: PrjComl% | DF1: =IFERROR((DE7+DF7)/(DE6+DF6),0)
B2: Cautions!! | C2: *Master OR | D2: =D1 | F2: *Sales Engineer | I2: Girish Sulakshane | W2: =V9 | AB2: =IF(ISBLANK(X9),0,(IF(ISBLANK(Y23),TODAY(),Y23)-X9+1)+IF(ISBLANK(Y30),TODAY(),Y30)-IF(ISBLANK(X28),TODAY(),X28)+1) | AE2: LD max/ wk | AM2: Calender Setting | AT2: Day | AX2: Weeklyoff setting1 (Shop) | BG2: Sat | BM2: Schedule Max Date | BU2: =MAX(W9:W55) | CA2: Print, % Completion | CI2: No | CO2: Current Plan | CY2: System Memory Area | DE2: ='@LeadT_Setting'!AR10 | DF2: ='@LeadT_Setting'!AR24
C3: *WOR No | F3: *Sales Manager | I3: Girish Sulakshane | AE3: LD max of OV | AM3: Days | AT3: =IF(AT2="Day",1,IF(AT2="Week",7,IF(AT2="2Day",2,IF(AT2="3Day",3,"")))) | AX3: Weeklyoff setting2 (Office) | BG3: Sat | BM3: Select Date | BU3: FirstMonth | CO3: Actual Plan | DE3: =IFERROR(DE7/DE6,0) | DF3: =IFERROR(DF7/DF6,0)
B4: IMS Doc Name | C4: FOX/IA/SALES/019 : Lead Time Chart | E4: Ver | F4: =ReadMe!H1 | AE4: LD remarks | AM4: =IF(OR(AM$6=$BG$2,AM$6=$BG$3),1,"") | AN4: =IF(OR(AN$6=$BG$2,AN$6=$BG$3),1,"") | AO4: =IF(OR(AO$6=$BG$2,AO$6=$BG$3),1,"") | AP4: =IF(OR(AP$6=$BG$2,AP$6=$BG$3),1,"") | AQ4: =IF(OR(AQ$6=$BG$2,AQ$6=$BG$3),1,"") | AR4: =IF(OR(AR$6=$BG$2,AR$6=$BG$3),1,"") | AS4: =IF(OR(AS$6=$BG$2,AS$6=$BG$3),1,"") | AT4: =IF(OR(AT$6=$BG$2,AT$6=$BG$3),1,"") | ... CU4: =IF(OR(CU$6=$BG$2,CU$6=$BG$3),1,"") | DE4: TEfforts | DF4: TEfforts
J5: =IFERROR(MATCH($B$1,#REF!,0)+8,"")
E6: BFT | F6: Ph | G6: TFO | H6: Phase ID | I6: Task Description | J6: Revised | K6: Plan-1 | L6: Revised | M6: Plan-2 | N6: Revised | O6: Plan-3 | P6: Original | Q6: Plan | R6: Ref | S6: Lead Time | T6: Intlk | U6: Effort Days | V6: Current | W6: Plan | X6: Actual | Y6: Dates | AE6: Warranty | AF6: Warranty of 24 Months from the date of Supply or 12 Months from the date of commissioning whichever is earlier | AG6: Scope | AH6: Scope | AI6: Scope | AJ6: Scope | AK6: Scope | AM6: =IFERROR(INDEX({"Sun","Mon","Tue","Wed","Thus","Fri","Sat"},WEEKDAY(AM7)),"") | AN6: =IFERROR(INDEX({"Sun","Mon","Tue","Wed","Thus","Fri","Sat"},WEEKDAY(AN7)),"") | AO6: =IFERROR(INDEX({"Sun","Mon","Tue","Wed","Thus","Fri","Sat"},WEEKDAY(AO7)),"") | AP6: =IFERROR(INDEX({"Sun","Mon","Tue","Wed","Thus","Fri","Sat"},WEEKDAY(AP7)),"") | AQ6: =IFERROR(INDEX({"Sun","Mon","Tue","Wed","Thus","Fri","Sat"},WEEKDAY(AQ7)),"") | AR6: =IFERROR(INDEX({"Sun","Mon","Tue","Wed","Thus","Fri","Sat"},WEEKDAY(AR7)),"") | AS6: =IFERROR(INDEX({"Sun","Mon","Tue","Wed","Thus","Fri","Sat"},WEEKDAY(AS7)),"") | AT6: =IFERROR(INDEX({"Sun","Mon","Tue","Wed","Thus","Fri","Sat"},WEEKDAY(AT7)),"") | ... CU6: =IFERROR(INDEX({"Sun","Mon","Tue","Wed","Thus","Fri","Sat"},WEEKDAY(CU7)),"") | DE6: =SUMIF(G:G,"SW",DG:DG) | DF6: =SUMIF(G:G,"EC",DG:DG)
C7: *Compulsory field | D7: SWE | E7: Buffer Time | F7: Ph | G7: TFO | H7: Phase ID | I7: Task Description | J7: Start Date | K7: End Date | L7: Start Date | M7: End Date | N7: Start Date | O7: End Date | P7: Start Date | Q7: End Date | R7: Lead Time | V7: Start Date | W7: End Date | X7: Start Date | Y7: End Date | Z7: % Complete | AA7: Exptd % Complete | AB7: Alert Date for 80% | AD7: Help required from | AF7: Remark | AG7: HW | AH7: SW | AI7: MFG | AJ7: Inst | AK7: COM | AL7: % Compl | AM7: =IF(WEEKDAY(MIN(V9:V55))<>7,IF($BU$3="SecondMonth",MIN(V9:V55)+30,MIN(V9:V55)-(WEEKDAY(MIN(V9:V55))-1)),IF($BU$3="SecondMonth",MIN(V9:V55)+30,MIN(V9:V55)-(WEEKDAY(MIN(V9:V55))-1))) | AN7: =IF(AM7<$BU$2,AM7+$AT$3,"") | AO7: =IF(AN7<$BU$2,AN7+$AT$3,"") | AP7: =IF(AO7<$BU$2,AO7+$AT$3,"") | AQ7: =IF(AP7<$BU$2,AP7+$AT$3,"") | AR7: =IF(AQ7<$BU$2,AQ7+$AT$3,"") | AS7: =IF(AR7<$BU$2,AR7+$AT$3,"") | AT7: =IF(AS7<$BU$2,AS7+$AT$3,"") | AU7: =IF(AT7<$BU$2,AT7+$AT$3,"") | ... CU7: =IF(CT7<$BU$2,CT7+$AT$3,"") | DE7: =SUMIF(G9:G55,"SW",DF9:DF55) | DF7: =SUMIF(G9:G55,"EC",DF9:DF55)
A8: FL | B8: FL | C8: FL | D8: FL | E8: FL | F8: FL | G8: FL | H8: FL | I8: FL | J8: FL | K8: FL | L8: FL | M8: FL | N8: FL | O8: FL | P8: FL | Q8: FL | R8: FL | S8: FL | T8: FL | U8: FL | V8: FL | W8: FL | X8: FL | Y8: FL | Z8: FL | AA8: FL | AB8: FL | AD8: FL | AF8: FL | AG8: FL | AH8: FL | AI8: FL | AJ8: FL | AK8: FL | AM8: FL | AN8: FL | AO8: FL | AP8: FL | AQ8: FL | AR8: FL | AS8: FL | AT8: FL | AU8: FL | AV8: FL | AW8: FL | AX8: FL | AY8: FL | AZ8: FL | BA8: FL | BB8: FL | BC8: FL | BD8: FL | BE8: FL | BF8: FL | BG8: FL | BH8: FL | BI8: FL | BJ8: FL | BK8: FL | BL8: FL | BM8: FL | BN8: FL | BO8: FL | BP8: FL | BQ8: FL | BR8: FL | BS8: FL | BT8: FL | BU8: FL | BV8: FL | BW8: FL | BX8: FL | BY8: FL | BZ8: FL | CA8: FL | CB8: FL | CC8: FL | CD8: FL | CE8: FL | CF8: FL | CG8: FL | CH8: FL | CI8: FL | CJ8: FL | CK8: FL | CL8: FL | CM8: FL | CN8: FL | CO8: FL | CP8: FL | CQ8: FL | CR8: FL | CS8: FL | CT8: FL | CU8: FL | CY8: PMREDActivity | CZ8: Exptd Compl Days | DA8: Act Compl Days | DB8: Exptd% | DC8: PLREDActivity | DD8: Progress Flag | DF8: BalEfforts | DG8: AssignedEfforts | DH8: AlertDt Yellow
A9: SW | C9: *PO Value in lacs | D9: 54 | F9: P1 | G9: SW | H9: P1-01 | I9: Project Scheduling | P9: 44353 | Q9: 44353 | R9: =IFERROR(INDEX('@LeadT_Setting'!$F$6:$J$52,MATCH(I9,'@LeadT_Setting'!$E$6:$E$52,0),MATCH(INDEX('@LeadT_Setting'!$AI$1:$AI$3,MATCH($A9,'@LeadT_Setting'!$AD$1:$AD$3,0),0),'@LeadT_Setting'!$F$1:$J$1,0)),0) | S9: 1 | U9: 0.001 | V9: =IFERROR(IF(S9>0,W9-S9+1,W9),"") | W9: =IFERROR(IF(S9>0,V10-1,V10),"") | X9: 44353 | Y9: 44353 | Z9: 1 | AA9: =IFERROR(IF(OR(U9<=0,TODAY()<V9),0,IF(TODAY()>=W9,1,((TODAY()-V9))/((W9-V9)))),0) | AB9: =IFERROR(IF(V9<>"",V9+(W9-V9)*0.8,""),"") | AG9: N | AH9: N | AI9: N | AJ9: N | AK9: N | AL9: =Z9 | CY9: =IF(OR(AND(TODAY()>W9,Z9<>1,DB9=1),AND(DB9>='@LeadT_Setting'!$AK$6,Z9<='@LeadT_Setting'!$AK$6),AND(Z9<(DB9-'@LeadT_Setting'!$AI$6),DB9>Z9,U9>0,DB9<'@LeadT_Setting'!$AK$6)),1,0) | CZ9: =IFERROR(AA9*U9,0) | DA9: =IFERROR(Z9*U9,0) | DB9: =IFERROR(IF(OR(U9<=0,TODAY()<V9),0,IF(TODAY()>=W9,1,((TODAY()-V9))/((W9-V9)))),0) | DC9: =IF(OR(AND(TODAY()>W9,Z9<>1,DB9=1),AND(DB9>='@LeadT_Setting'!$AK$6,Z9<='@LeadT_Setting'!$AK$6),AND(Z9<(DB9-'@LeadT_Setting'!$AJ$6),DB9>Z9,U9>0)),1,0) | DD9: =IF(Z9=1,0,IF(AD9="Engineering",1,IF(AD9="Purchase",2,IF(AD9="Software",3,IF(AD9="Project Management",4,IF(AD9="Manufacturing",5,IF(AD9="Sales",6,IF(AD9="Client",7,0)))))))) | DH9: =IF(OR(AND(U9>0,TODAY()>=AB9,Z9<80%,NOT(ISBLANK(AB9))),AND(Z9<>1,U9>0,$V9<TODAY(),ISBLANK($Y9))),1,0)
A10: SW | C10: *Customer Name | D10: CORE ENERGY SYSTEMS PVT LTD. | F10: P1 | G10: SW | H10: P1-02 | I10: Internal KOM | P10: 44354 | Q10: 44354 | R10: =IFERROR(INDEX('@LeadT_Setting'!$F$6:$J$52,MATCH(I10,'@LeadT_Setting'!$E$6:$E$52,0),MATCH(INDEX('@LeadT_Setting'!$AI$1:$AI$3,MATCH($A10,'@LeadT_Setting'!$AD$1:$AD$3,0),0),'@LeadT_Setting'!$F$1:$J$1,0)),0) | S10: 1 | U10: 0.001 | V10: =IF(ISBLANK(C28),"",C28) | W10: =IFERROR(IF(S10=0,V10,V10+S10-1),"") | X10: 44354 | Y10: 44354 | Z10: 1 | AA10: =IFERROR(IF(OR(U10<=0,TODAY()<V10),0,IF(TODAY()>=W10,1,((TODAY()-V10))/((W10-V10)))),0) | AB10: =IFERROR(IF(V10<>"",V10+(W10-V10)*0.8,""),"") | AI10: Scope Details | AL10: =Z10 | CY10: =IF(OR(AND(TODAY()>W10,Z10<>1,DB10=1),AND(DB10>='@LeadT_Setting'!$AK$6,Z10<='@LeadT_Setting'!$AK$6),AND(Z10<(DB10-'@LeadT_Setting'!$AI$6),DB10>Z10,U10>0,DB10<'@LeadT_Setting'!$AK$6)),1,0) | CZ10: =IFERROR(AA10*U10,0) | DA10: =IFERROR(Z10*U10,0) | DB10: =IFERROR(IF(OR(U10<=0,TODAY()<V10),0,IF(TODAY()>=W10,1,((TODAY()-V10))/((W10-V10)))),0) | DC10: =IF(OR(AND(TODAY()>W10,Z10<>1,DB10=1),AND(DB10>='@LeadT_Setting'!$AK$6,Z10<='@LeadT_Setting'!$AK$6),AND(Z10<(DB10-'@LeadT_Setting'!$AJ$6),DB10>Z10,U10>0)),1,0) | DD10: =IF(Z10=1,0,IF(AD10="Engineering",1,IF(AD10="Purchase",2,IF(AD10="Software",3,IF(AD10="Project Management",4,IF(AD10="Manufacturing",5,IF(AD10="Sales",6,IF(AD10="Client",7,0)))))))) | DH10: =IF(OR(AND(U10>0,TODAY()>=AB10,Z10<80%,NOT(ISBLANK(AB10))),AND(Z10<>1,U10>0,$V10<TODAY(),ISBLANK($Y10))),1,0)
A11: SW | C11: End Customer | D11: NPCIL Kudankulam Power Project | F11: P2 | G11: SW | H11: P2-01 | I11: SW I/P Collection | P11: 45085 | Q11: 45089 | R11: =IFERROR(INDEX('@LeadT_Setting'!$F$6:$J$52,MATCH(I11,'@LeadT_Setting'!$E$6:$E$52,0),MATCH(INDEX('@LeadT_Setting'!$AI$1:$AI$3,MATCH($A11,'@LeadT_Setting'!$AD$1:$AD$3,0),0),'@LeadT_Setting'!$F$1:$J$1,0)),0) | S11: 5 | U11: 3 | V11: =IFERROR(IF(OR(S11=0,S11=""),W11,W11-S11+1),"") | W11: =IFERROR(V12-1+E11,"") | X11: 45085 | Y11: 45089 | Z11: 1 | AA11: =IFERROR(IF(OR(U11<=0,TODAY()<V11),0,IF(TODAY()>=W11,1,((TODAY()-V11))/((W11-V11)))),0) | AB11: =IFERROR(IF(V11<>"",V11+(W11-V11)*0.8,""),"") | AL11: =Z11 | CY11: =IF(OR(AND(TODAY()>W11,Z11<>1,DB11=1),AND(DB11>='@LeadT_Setting'!$AK$6,Z11<='@LeadT_Setting'!$AK$6),AND(Z11<(DB11-'@LeadT_Setting'!$AI$6),DB11>Z11,U11>0,DB11<'@LeadT_Setting'!$AK$6)),1,0) | CZ11: =IFERROR(AA11*U11,0) | DA11: =IFERROR(Z11*U11,0) | DB11: =IFERROR(IF(OR(U11<=0,TODAY()<V11),0,IF(TODAY()>=W11,1,((TODAY()-V11))/((W11-V11)))),0) | DC11: =IF(OR(AND(TODAY()>W11,Z11<>1,DB11=1),AND(DB11>='@LeadT_Setting'!$AK$6,Z11<='@LeadT_Setting'!$AK$6),AND(Z11<(DB11-'@LeadT_Setting'!$AJ$6),DB11>Z11,U11>0)),1,0) | DD11: =IF(Z11=1,0,IF(AD11="Engineering",1,IF(AD11="Purchase",2,IF(AD11="Software",3,IF(AD11="Project Management",4,IF(AD11="Manufacturing",5,IF(AD11="Sales",6,IF(AD11="Client",7,0)))))))) | DF11: =Z11*U11 | DG11: =U11 | DH11: =IF(OR(AND(U11>0,TODAY()>=AB11,Z11<80%,NOT(ISBLANK(AB11))),AND(Z11<>1,U11>0,$V11<TODAY(),ISBLANK($Y11))),1,0)
A12: SW | C12: Consultant | D12: Reliance Infrastructure Ltd. | F12: P2 | G12: SW | H12: P2-02 | I12: SW Design Preparation | P12: 45090 | Q12: 45095 | R12: =IFERROR(INDEX('@LeadT_Setting'!$F$6:$J$52,MATCH(I12,'@LeadT_Setting'!$E$6:$E$52,0),MATCH(INDEX('@LeadT_Setting'!$AI$1:$AI$3,MATCH($A12,'@LeadT_Setting'!$AD$1:$AD$3,0),0),'@LeadT_Setting'!$F$1:$J$1,0)),0) | S12: 6 | T12: P1-03 | U12: 1 | V12: =IFERROR(IF(OR(S12=0,S12=""),W12,W12-S12+1),"") | W12: =IFERROR(IF(S13=0,V13,V13-1),"") | X12: 45090 | Y12: 45095 | Z12: 1 | AA12: =IFERROR(IF(OR(U12<=0,TODAY()<V12),0,IF(TODAY()>=W12,1,((TODAY()-V12))/((W12-V12)))),0) | AB12: =IFERROR(IF(V12<>"",V12+(W12-V12)*0.8,""),"") | AL12: =Z12 | CY12: =IF(OR(AND(TODAY()>W12,Z12<>1,DB12=1),AND(DB12>='@LeadT_Setting'!$AK$6,Z12<='@LeadT_Setting'!$AK$6),AND(Z12<(DB12-'@LeadT_Setting'!$AI$6),DB12>Z12,U12>0,DB12<'@LeadT_Setting'!$AK$6)),1,0) | CZ12: =IFERROR(AA12*U12,0) | DA12: =IFERROR(Z12*U12,0) | DB12: =IFERROR(IF(OR(U12<=0,TODAY()<V12),0,IF(TODAY()>=W12,1,((TODAY()-V12))/((W12-V12)))),0) | DC12: =IF(OR(AND(TODAY()>W12,Z12<>1,DB12=1),AND(DB12>='@LeadT_Setting'!$AK$6,Z12<='@LeadT_Setting'!$AK$6),AND(Z12<(DB12-'@LeadT_Setting'!$AJ$6),DB12>Z12,U12>0)),1,0) | DD12: =IF(Z12=1,0,IF(AD12="Engineering",1,IF(AD12="Purchase",2,IF(AD12="Software",3,IF(AD12="Project Management",4,IF(AD12="Manufacturing",5,IF(AD12="Sales",6,IF(AD12="Client",7,0)))))))) | DF12: =Z12*U12 | DG12: =U12 | DH12: =IF(OR(AND(U12>0,TODAY()>=AB12,Z12<80%,NOT(ISBLANK(AB12))),AND(Z12<>1,U12>0,$V12<TODAY(),ISBLANK($Y12))),1,0)
A13: SW | C13: *Project Desc. | D13: Supply of PLC SCADA Package for Compressor System for NPCIL KKNPP 3 & 4 | F13: P2 | G13: SW | H13: P2-03 | I13: SW Design Validation | P13: 45096 | Q13: 45096 | R13: =IFERROR(INDEX('@LeadT_Setting'!$F$6:$J$52,MATCH(I13,'@LeadT_Setting'!$E$6:$E$52,0),MATCH(INDEX('@LeadT_Setting'!$AI$1:$AI$3,MATCH($A13,'@LeadT_Setting'!$AD$1:$AD$3,0),0),'@LeadT_Setting'!$F$1:$J$1,0)),0) | S13: 1 | U13: 2 | V13: =IFERROR(IF(OR(S13=0,S13=""),W13,W13-S13+1),"") | W13: =IFERROR(IF(S14=0,V14,V14-1),"") | X13: 45096 | Y13: 45096 | Z13: 1 | AA13: =IFERROR(IF(OR(U13<=0,TODAY()<V13),0,IF(TODAY()>=W13,1,((TODAY()-V13))/((W13-V13)))),0) | AB13: =IFERROR(IF(V13<>"",V13+(W13-V13)*0.8,""),"") | AL13: =Z13 | CY13: =IF(OR(AND(TODAY()>W13,Z13<>1,DB13=1),AND(DB13>='@LeadT_Setting'!$AK$6,Z13<='@LeadT_Setting'!$AK$6),AND(Z13<(DB13-'@LeadT_Setting'!$AI$6),DB13>Z13,U13>0,DB13<'@LeadT_Setting'!$AK$6)),1,0) | CZ13: =IFERROR(AA13*U13,0) | DA13: =IFERROR(Z13*U13,0) | DB13: =IFERROR(IF(OR(U13<=0,TODAY()<V13),0,IF(TODAY()>=W13,1,((TODAY()-V13))/((W13-V13)))),0) | DC13: =IF(OR(AND(TODAY()>W13,Z13<>1,DB13=1),AND(DB13>='@LeadT_Setting'!$AK$6,Z13<='@LeadT_Setting'!$AK$6),AND(Z13<(DB13-'@LeadT_Setting'!$AJ$6),DB13>Z13,U13>0)),1,0) | DD13: =IF(Z13=1,0,IF(AD13="Engineering",1,IF(AD13="Purchase",2,IF(AD13="Software",3,IF(AD13="Project Management",4,IF(AD13="Manufacturing",5,IF(AD13="Sales",6,IF(AD13="Client",7,0)))))))) | DF13: =Z13*U13 | DG13: =U13 | DH13: =IF(OR(AND(U13>0,TODAY()>=AB13,Z13<80%,NOT(ISBLANK(AB13))),AND(Z13<>1,U13>0,$V13<TODAY(),ISBLANK($Y13))),1,0)
A14: SW | C14: *Section | D14: PLC | F14: P2 | G14: SW | H14: P2-04 | I14: SW Documents Submission | P14: 45097 | Q14: 45097 | R14: =IFERROR(INDEX('@LeadT_Setting'!$F$6:$J$52,MATCH(I14,'@LeadT_Setting'!$E$6:$E$52,0),MATCH(INDEX('@LeadT_Setting'!$AI$1:$AI$3,MATCH($A14,'@LeadT_Setting'!$AD$1:$AD$3,0),0),'@LeadT_Setting'!$F$1:$J$1,0)),0) | S14: 1 | U14: 3 | V14: =IFERROR(IF(OR(S14=0,S14=""),W14,W14-S14+1),"") | W14: =IFERROR(IF(S15=0,V15,V15-1),"") | X14: 45097 | Y14: 45097 | Z14: 1 | AA14: =IFERROR(IF(OR(U14<=0,TODAY()<V14),0,IF(TODAY()>=W14,1,((TODAY()-V14))/((W14-V14)))),0) | AB14: =IFERROR(IF(V14<>"",V14+(W14-V14)*0.8,""),"") | AL14: =Z14 | CY14: =IF(OR(AND(TODAY()>W14,Z14<>1,DB14=1),AND(DB14>='@LeadT_Setting'!$AK$6,Z14<='@LeadT_Setting'!$AK$6),AND(Z14<(DB14-'@LeadT_Setting'!$AI$6),DB14>Z14,U14>0,DB14<'@LeadT_Setting'!$AK$6)),1,0) | CZ14: =IFERROR(AA14*U14,0) | DA14: =IFERROR(Z14*U14,0) | DB14: =IFERROR(IF(OR(U14<=0,TODAY()<V14),0,IF(TODAY()>=W14,1,((TODAY()-V14))/((W14-V14)))),0) | DC14: =IF(OR(AND(TODAY()>W14,Z14<>1,DB14=1),AND(DB14>='@LeadT_Setting'!$AK$6,Z14<='@LeadT_Setting'!$AK$6),AND(Z14<(DB14-'@LeadT_Setting'!$AJ$6),DB14>Z14,U14>0)),1,0) | DD14: =IF(Z14=1,0,IF(AD14="Engineering",1,IF(AD14="Purchase",2,IF(AD14="Software",3,IF(AD14="Project Management",4,IF(AD14="Manufacturing",5,IF(AD14="Sales",6,IF(AD14="Client",7,0)))))))) | DF14: =Z14*U14 | DG14: =U14 | DH14: =IF(OR(AND(U14>0,TODAY()>=AB14,Z14<80%,NOT(ISBLANK(AB14))),AND(Z14<>1,U14>0,$V14<TODAY(),ISBLANK($Y14))),1,0)
A15: SW | F15: P3 | G15: SW | H15: P3-01 | I15: SW Documents Approval | P15: 45098 | Q15: 45105 | R15: =IFERROR(INDEX('@LeadT_Setting'!$F$6:$J$52,MATCH(I15,'@LeadT_Setting'!$E$6:$E$52,0),MATCH(INDEX('@LeadT_Setting'!$AI$1:$AI$3,MATCH($A15,'@LeadT_Setting'!$AD$1:$AD$3,0),0),'@LeadT_Setting'!$F$1:$J$1,0)),0) | S15: 8 | U15: 2 | V15: =IFERROR(IF(OR(S15=0,S15=""),W15,W15-S15+1),"") | W15: =IFERROR(IF(S16=0,V16,V16-1),"") | X15: 45098 | Y15: 45105 | Z15: 1 | AA15: =IFERROR(IF(OR(U15<=0,TODAY()<V15),0,IF(TODAY()>=W15,1,((TODAY()-V15))/((W15-V15)))),0) | AB15: =IFERROR(IF(V15<>"",V15+(W15-V15)*0.8,""),"") | AL15: =Z15 | CY15: =IF(OR(AND(TODAY()>W15,Z15<>1,DB15=1),AND(DB15>='@LeadT_Setting'!$AK$6,Z15<='@LeadT_Setting'!$AK$6),AND(Z15<(DB15-'@LeadT_Setting'!$AI$6),DB15>Z15,U15>0,DB15<'@LeadT_Setting'!$AK$6)),1,0) | CZ15: =IFERROR(AA15*U15,0) | DA15: =IFERROR(Z15*U15,0) | DB15: =IFERROR(IF(OR(U15<=0,TODAY()<V15),0,IF(TODAY()>=W15,1,((TODAY()-V15))/((W15-V15)))),0) | DC15: =IF(OR(AND(TODAY()>W15,Z15<>1,DB15=1),AND(DB15>='@LeadT_Setting'!$AK$6,Z15<='@LeadT_Setting'!$AK$6),AND(Z15<(DB15-'@LeadT_Setting'!$AJ$6),DB15>Z15,U15>0)),1,0) | DD15: =IF(Z15=1,0,IF(AD15="Engineering",1,IF(AD15="Purchase",2,IF(AD15="Software",3,IF(AD15="Project Management",4,IF(AD15="Manufacturing",5,IF(AD15="Sales",6,IF(AD15="Client",7,0)))))))) | DF15: =Z15*U15 | DG15: =U15 | DH15: =IF(OR(AND(U15>0,TODAY()>=AB15,Z15<80%,NOT(ISBLANK(AB15))),AND(Z15<>1,U15>0,$V15<TODAY(),ISBLANK($Y15))),1,0)
A16: SW | B16: Actual man-days | D16: ='@LeadT_Setting'!AI3 | F16: P3 | G16: SW | H16: P3-02 | I16: Drive SW | P16: 45106 | Q16: 45135 | R16: =IFERROR(INDEX('@LeadT_Setting'!$F$6:$J$52,MATCH(I16,'@LeadT_Setting'!$E$6:$E$52,0),MATCH(INDEX('@LeadT_Setting'!$AI$1:$AI$3,MATCH($A16,'@LeadT_Setting'!$AD$1:$AD$3,0),0),'@LeadT_Setting'!$F$1:$J$1,0)),0) | S16: 30 | U16: 0 | V16: =IFERROR(IF(OR(S16=0,S16=""),W16,W16-S16+1),"") | W16: =W17 | X16: 45106 | Y16: 45135 | Z16: 1 | AA16: =IFERROR(IF(OR(U16<=0,TODAY()<V16),0,IF(TODAY()>=W16,1,((TODAY()-V16))/((W16-V16)))),0) | AB16: =IFERROR(IF(V16<>"",V16+(W16-V16)*0.8,""),"") | AL16: =Z16 | CY16: =IF(OR(AND(TODAY()>W16,Z16<>1,DB16=1),AND(DB16>='@LeadT_Setting'!$AK$6,Z16<='@LeadT_Setting'!$AK$6),AND(Z16<(DB16-'@LeadT_Setting'!$AI$6),DB16>Z16,U16>0,DB16<'@LeadT_Setting'!$AK$6)),1,0) | CZ16: =IFERROR(AA16*U16,0) | DA16: =IFERROR(Z16*U16,0) | DB16: =IFERROR(IF(OR(U16<=0,TODAY()<V16),0,IF(TODAY()>=W16,1,((TODAY()-V16))/((W16-V16)))),0) | DC16: =IF(OR(AND(TODAY()>W16,Z16<>1,DB16=1),AND(DB16>='@LeadT_Setting'!$AK$6,Z16<='@LeadT_Setting'!$AK$6),AND(Z16<(DB16-'@LeadT_Setting'!$AJ$6),DB16>Z16,U16>0)),1,0) | DD16: =IF(Z16=1,0,IF(AD16="Engineering",1,IF(AD16="Purchase",2,IF(AD16="Software",3,IF(AD16="Project Management",4,IF(AD16="Manufacturing",5,IF(AD16="Sales",6,IF(AD16="Client",7,0)))))))) | DF16: =Z16*U16 | DG16: =U16 | DH16: =IF(OR(AND(U16>0,TODAY()>=AB16,Z16<80%,NOT(ISBLANK(AB16))),AND(Z16<>1,U16>0,$V16<TODAY(),ISBLANK($Y16))),1,0)
A17: SW | B17: 0 | C17: *SW Efforts | D17: 35 | F17: P3 | G17: SW | H17: P3-03 | I17: PLC SW | P17: 45106 | Q17: 45135 | U17: 23 | V17: =V16 | W17: =W18 | X17: 45106 | Y17: 45135 | Z17: 1 | AA17: =IFERROR(IF(OR(U17<=0,TODAY()<V17),0,IF(TODAY()>=W17,1,((TODAY()-V17))/((W17-V17)))),0) | AB17: =IFERROR(IF(V17<>"",V17+(W17-V17)*0.8,""),"") | AL17: =Z17 | CY17: =IF(OR(AND(TODAY()>W17,Z17<>1,DB17=1),AND(DB17>='@LeadT_Setting'!$AK$6,Z17<='@LeadT_Setting'!$AK$6),AND(Z17<(DB17-'@LeadT_Setting'!$AI$6),DB17>Z17,U17>0,DB17<'@LeadT_Setting'!$AK$6)),1,0) | CZ17: =IFERROR(AA17*U17,0) | DA17: =IFERROR(Z17*U17,0) | DB17: =IFERROR(IF(OR(U17<=0,TODAY()<V17),0,IF(TODAY()>=W17,1,((TODAY()-V17))/((W17-V17)))),0) | DC17: =IF(OR(AND(TODAY()>W17,Z17<>1,DB17=1),AND(DB17>='@LeadT_Setting'!$AK$6,Z17<='@LeadT_Setting'!$AK$6),AND(Z17<(DB17-'@LeadT_Setting'!$AJ$6),DB17>Z17,U17>0)),1,0) | DD17: =IF(Z17=1,0,IF(AD17="Engineering",1,IF(AD17="Purchase",2,IF(AD17="Software",3,IF(AD17="Project Management",4,IF(AD17="Manufacturing",5,IF(AD17="Sales",6,IF(AD17="Client",7,0)))))))) | DF17: =Z17*U17 | DG17: =U17 | DH17: =IF(OR(AND(U17>0,TODAY()>=AB17,Z17<80%,NOT(ISBLANK(AB17))),AND(Z17<>1,U17>0,$V17<TODAY(),ISBLANK($Y17))),1,0)
A18: SW | F18: P3 | G18: SW | H18: P3-04 | I18: HMI/SCADA | P18: 45106 | Q18: 45135 | U18: 10 | V18: =V17 | W18: =W19 | X18: 45106 | Y18: 45135 | Z18: 1 | AA18: =IFERROR(IF(OR(U18<=0,TODAY()<V18),0,IF(TODAY()>=W18,1,((TODAY()-V18))/((W18-V18)))),0) | AB18: =IFERROR(IF(V18<>"",V18+(W18-V18)*0.8,""),"") | AL18: =Z18 | CY18: =IF(OR(AND(TODAY()>W18,Z18<>1,DB18=1),AND(DB18>='@LeadT_Setting'!$AK$6,Z18<='@LeadT_Setting'!$AK$6),AND(Z18<(DB18-'@LeadT_Setting'!$AI$6),DB18>Z18,U18>0,DB18<'@LeadT_Setting'!$AK$6)),1,0) | CZ18: =IFERROR(AA18*U18,0) | DA18: =IFERROR(Z18*U18,0) | DB18: =IFERROR(IF(OR(U18<=0,TODAY()<V18),0,IF(TODAY()>=W18,1,((TODAY()-V18))/((W18-V18)))),0) | DC18: =IF(OR(AND(TODAY()>W18,Z18<>1,DB18=1),AND(DB18>='@LeadT_Setting'!$AK$6,Z18<='@LeadT_Setting'!$AK$6),AND(Z18<(DB18-'@LeadT_Setting'!$AJ$6),DB18>Z18,U18>0)),1,0) | DD18: =IF(Z18=1,0,IF(AD18="Engineering",1,IF(AD18="Purchase",2,IF(AD18="Software",3,IF(AD18="Project Management",4,IF(AD18="Manufacturing",5,IF(AD18="Sales",6,IF(AD18="Client",7,0)))))))) | DF18: =Z18*U18 | DG18: =U18 | DH18: =IF(OR(AND(U18>0,TODAY()>=AB18,Z18<80%,NOT(ISBLANK(AB18))),AND(Z18<>1,U18>0,$V18<TODAY(),ISBLANK($Y18))),1,0)
A19: SW | F19: P3 | G19: SW | H19: P3-05 | I19: Report | P19: 45106 | Q19: 45135 | U19: 5 | V19: =V18 | W19: =W20 | X19: 45106 | Y19: 45135 | Z19: 1 | AA19: =IFERROR(IF(OR(U19<=0,TODAY()<V19),0,IF(TODAY()>=W19,1,((TODAY()-V19))/((W19-V19)))),0) | AB19: =IFERROR(IF(V19<>"",V19+(W19-V19)*0.8,""),"") | AL19: =Z19 | CY19: =IF(OR(AND(TODAY()>W19,Z19<>1,DB19=1),AND(DB19>='@LeadT_Setting'!$AK$6,Z19<='@LeadT_Setting'!$AK$6),AND(Z19<(DB19-'@LeadT_Setting'!$AI$6),DB19>Z19,U19>0,DB19<'@LeadT_Setting'!$AK$6)),1,0) | CZ19: =IFERROR(AA19*U19,0) | DA19: =IFERROR(Z19*U19,0) | DB19: =IFERROR(IF(OR(U19<=0,TODAY()<V19),0,IF(TODAY()>=W19,1,((TODAY()-V19))/((W19-V19)))),0) | DC19: =IF(OR(AND(TODAY()>W19,Z19<>1,DB19=1),AND(DB19>='@LeadT_Setting'!$AK$6,Z19<='@LeadT_Setting'!$AK$6),AND(Z19<(DB19-'@LeadT_Setting'!$AJ$6),DB19>Z19,U19>0)),1,0) | DD19: =IF(Z19=1,0,IF(AD19="Engineering",1,IF(AD19="Purchase",2,IF(AD19="Software",3,IF(AD19="Project Management",4,IF(AD19="Manufacturing",5,IF(AD19="Sales",6,IF(AD19="Client",7,0)))))))) | DF19: =Z19*U19 | DG19: =U19 | DH19: =IF(OR(AND(U19>0,TODAY()>=AB19,Z19<80%,NOT(ISBLANK(AB19))),AND(Z19<>1,U19>0,$V19<TODAY(),ISBLANK($Y19))),1,0)
A20: SW | F20: P3 | G20: SW | H20: P3-06 | I20: Internal testing | P20: 45106 | Q20: 45135 | U20: 4 | V20: =V19 | W20: =IFERROR(IF(S21=0,V21,V21-1),"") | X20: 45106 | Y20: 45135 | Z20: 1 | AA20: =IFERROR(IF(OR(U20<=0,TODAY()<V20),0,IF(TODAY()>=W20,1,((TODAY()-V20))/((W20-V20)))),0) | AB20: =IFERROR(IF(V20<>"",V20+(W20-V20)*0.8,""),"") | AL20: =Z20 | CY20: =IF(OR(AND(TODAY()>W20,Z20<>1,DB20=1),AND(DB20>='@LeadT_Setting'!$AK$6,Z20<='@LeadT_Setting'!$AK$6),AND(Z20<(DB20-'@LeadT_Setting'!$AI$6),DB20>Z20,U20>0,DB20<'@LeadT_Setting'!$AK$6)),1,0) | CZ20: =IFERROR(AA20*U20,0) | DA20: =IFERROR(Z20*U20,0) | DB20: =IFERROR(IF(OR(U20<=0,TODAY()<V20),0,IF(TODAY()>=W20,1,((TODAY()-V20))/((W20-V20)))),0) | DC20: =IF(OR(AND(TODAY()>W20,Z20<>1,DB20=1),AND(DB20>='@LeadT_Setting'!$AK$6,Z20<='@LeadT_Setting'!$AK$6),AND(Z20<(DB20-'@LeadT_Setting'!$AJ$6),DB20>Z20,U20>0)),1,0) | DD20: =IF(Z20=1,0,IF(AD20="Engineering",1,IF(AD20="Purchase",2,IF(AD20="Software",3,IF(AD20="Project Management",4,IF(AD20="Manufacturing",5,IF(AD20="Sales",6,IF(AD20="Client",7,0)))))))) | DF20: =Z20*U20 | DG20: =U20 | DH20: =IF(OR(AND(U20>0,TODAY()>=AB20,Z20<80%,NOT(ISBLANK(AB20))),AND(Z20<>1,U20>0,$V20<TODAY(),ISBLANK($Y20))),1,0)
A21: SW | F21: P3 | G21: SW | H21: P3-07 | I21: SW FAT Call with Test Report | P21: 45136 | Q21: 45139 | R21: =IFERROR(INDEX('@LeadT_Setting'!$F$6:$J$52,MATCH(I21,'@LeadT_Setting'!$E$6:$E$52,0),MATCH(INDEX('@LeadT_Setting'!$AI$1:$AI$3,MATCH($A21,'@LeadT_Setting'!$AD$1:$AD$3,0),0),'@LeadT_Setting'!$F$1:$J$1,0)),0) | S21: 4 | U21: 1 | V21: =IFERROR(IF(OR(S21=0,S21=""),W21,W21-S21+1),"") | W21: =IFERROR(IF(S22=0,V22,V22-1),"") | X21: 45136 | Y21: 45139 | Z21: 1 | AA21: =IFERROR(IF(OR(U21<=0,TODAY()<V21),0,IF(TODAY()>=W21,1,((TODAY()-V21))/((W21-V21)))),0) | AB21: =IFERROR(IF(V21<>"",V21+(W21-V21)*0.8,""),"") | AL21: =Z21 | CY21: =IF(OR(AND(TODAY()>W21,Z21<>1,DB21=1),AND(DB21>='@LeadT_Setting'!$AK$6,Z21<='@LeadT_Setting'!$AK$6),AND(Z21<(DB21-'@LeadT_Setting'!$AI$6),DB21>Z21,U21>0,DB21<'@LeadT_Setting'!$AK$6)),1,0) | CZ21: =IFERROR(AA21*U21,0) | DA21: =IFERROR(Z21*U21,0) | DB21: =IFERROR(IF(OR(U21<=0,TODAY()<V21),0,IF(TODAY()>=W21,1,((TODAY()-V21))/((W21-V21)))),0) | DC21: =IF(OR(AND(TODAY()>W21,Z21<>1,DB21=1),AND(DB21>='@LeadT_Setting'!$AK$6,Z21<='@LeadT_Setting'!$AK$6),AND(Z21<(DB21-'@LeadT_Setting'!$AJ$6),DB21>Z21,U21>0)),1,0) | DD21: =IF(Z21=1,0,IF(AD21="Engineering",1,IF(AD21="Purchase",2,IF(AD21="Software",3,IF(AD21="Project Management",4,IF(AD21="Manufacturing",5,IF(AD21="Sales",6,IF(AD21="Client",7,0)))))))) | DF21: =Z21*U21 | DG21: =U21 | DH21: =IF(OR(AND(U21>0,TODAY()>=AB21,Z21<80%,NOT(ISBLANK(AB21))),AND(Z21<>1,U21>0,$V21<TODAY(),ISBLANK($Y21))),1,0)
A22: SW | F22: P3 | G22: SW | H22: P3-08 | I22: SW FAT | P22: 45140 | Q22: 45141 | R22: =IFERROR(INDEX('@LeadT_Setting'!$F$6:$J$52,MATCH(I22,'@LeadT_Setting'!$E$6:$E$52,0),MATCH(INDEX('@LeadT_Setting'!$AI$1:$AI$3,MATCH($A22,'@LeadT_Setting'!$AD$1:$AD$3,0),0),'@LeadT_Setting'!$F$1:$J$1,0)),0) | S22: 2 | U22: 5 | V22: =IF(ISBLANK(C30),"",C30) | W22: =IFERROR(IF($S22<>"",IF(OR(V22=0,V22=""),V22,V22+S22-1),""),"") | X22: 45140 | Y22: 45141 | Z22: 1 | AA22: =IFERROR(IF(OR(U22<=0,TODAY()<V22),0,IF(TODAY()>=W22,1,((TODAY()-V22))/((W22-V22)))),0) | AB22: =IFERROR(IF(V22<>"",V22+(W22-V22)*0.8,""),"") | AL22: =Z22 | CY22: =IF(OR(AND(TODAY()>W22,Z22<>1,DB22=1),AND(DB22>='@LeadT_Setting'!$AK$6,Z22<='@LeadT_Setting'!$AK$6),AND(Z22<(DB22-'@LeadT_Setting'!$AI$6),DB22>Z22,U22>0,DB22<'@LeadT_Setting'!$AK$6)),1,0) | CZ22: =IFERROR(AA22*U22,0) | DA22: =IFERROR(Z22*U22,0) | DB22: =IFERROR(IF(OR(U22<=0,TODAY()<V22),0,IF(TODAY()>=W22,1,((TODAY()-V22))/((W22-V22)))),0) | DC22: =IF(OR(AND(TODAY()>W22,Z22<>1,DB22=1),AND(DB22>='@LeadT_Setting'!$AK$6,Z22<='@LeadT_Setting'!$AK$6),AND(Z22<(DB22-'@LeadT_Setting'!$AJ$6),DB22>Z22,U22>0)),1,0) | DD22: =IF(Z22=1,0,IF(AD22="Engineering",1,IF(AD22="Purchase",2,IF(AD22="Software",3,IF(AD22="Project Management",4,IF(AD22="Manufacturing",5,IF(AD22="Sales",6,IF(AD22="Client",7,0)))))))) | DF22: =Z22*U22 | DG22: =U22 | DH22: =IF(OR(AND(U22>0,TODAY()>=AB22,Z22<80%,NOT(ISBLANK(AB22))),AND(Z22<>1,U22>0,$V22<TODAY(),ISBLANK($Y22))),1,0)
A23: SW | F23: P3 | G23: SW | H23: P3-09 | I23: SW FAT Compliance | P23: 45142 | Q23: 45143 | R23: =IFERROR(INDEX('@LeadT_Setting'!$F$6:$J$52,MATCH(I23,'@LeadT_Setting'!$E$6:$E$52,0),MATCH(INDEX('@LeadT_Setting'!$AI$1:$AI$3,MATCH($A23,'@LeadT_Setting'!$AD$1:$AD$3,0),0),'@LeadT_Setting'!$F$1:$J$1,0)),0) | S23: 2 | U23: 2 | V23: =IFERROR(IF(S23=0,W22,W22+1),"") | W23: =IFERROR(IF(OR(S23="",S23=0),V23,V23+S23-1),"") | X23: 45142 | Y23: 45143 | Z23: 1 | AA23: =IFERROR(IF(OR(U23<=0,TODAY()<V23),0,IF(TODAY()>=W23,1,((TODAY()-V23))/((W23-V23)))),0) | AB23: =IFERROR(IF(V23<>"",V23+(W23-V23)*0.8,""),"") | AL23: =Z23 | CY23: =IF(OR(AND(TODAY()>W23,Z23<>1,DB23=1),AND(DB23>='@LeadT_Setting'!$AK$6,Z23<='@LeadT_Setting'!$AK$6),AND(Z23<(DB23-'@LeadT_Setting'!$AI$6),DB23>Z23,U23>0,DB23<'@LeadT_Setting'!$AK$6)),1,0) | CZ23: =IFERROR(AA23*U23,0) | DA23: =IFERROR(Z23*U23,0) | DB23: =IFERROR(IF(OR(U23<=0,TODAY()<V23),0,IF(TODAY()>=W23,1,((TODAY()-V23))/((W23-V23)))),0) | DC23: =IF(OR(AND(TODAY()>W23,Z23<>1,DB23=1),AND(DB23>='@LeadT_Setting'!$AK$6,Z23<='@LeadT_Setting'!$AK$6),AND(Z23<(DB23-'@LeadT_Setting'!$AJ$6),DB23>Z23,U23>0)),1,0) | DD23: =IF(Z23=1,0,IF(AD23="Engineering",1,IF(AD23="Purchase",2,IF(AD23="Software",3,IF(AD23="Project Management",4,IF(AD23="Manufacturing",5,IF(AD23="Sales",6,IF(AD23="Client",7,0)))))))) | DF23: =Z23*U23 | DG23: =U23 | DH23: =IF(OR(AND(U23>0,TODAY()>=AB23,Z23<80%,NOT(ISBLANK(AB23))),AND(Z23<>1,U23>0,$V23<TODAY(),ISBLANK($Y23))),1,0)
A24: EC | F24: P4 | G24: EC | H24: P4-01 | I24: Installation | R24: =S24 | S24: 0 | U24: 0 | V24: =IF(ISBLANK(C31),"",C31) | W24: =IFERROR(IF(S24=0,V24,V24+S24-1),"") | Z24: 1 | AA24: =IFERROR(IF(OR(U24<=0,TODAY()<V24),0,IF(TODAY()>=W24,1,((TODAY()-V24))/((W24-V24)))),0) | AB24: =IFERROR(IF(V24<>"",V24+(W24-V24)*0.8,""),"") | AL24: =Z24 | CY24: =IF(OR(AND(TODAY()>W24,Z24<>1,DB24=1),AND(DB24>='@LeadT_Setting'!$AK$6,Z24<='@LeadT_Setting'!$AK$6),AND(Z24<(DB24-'@LeadT_Setting'!$AI$6),DB24>Z24,U24>0,DB24<'@LeadT_Setting'!$AK$6)),1,0) | CZ24: =IFERROR(AA24*U24,0) | DA24: =IFERROR(Z24*U24,0) | DB24: =IFERROR(IF(OR(U24<=0,TODAY()<V24),0,IF(TODAY()>=W24,1,((TODAY()-V24))/((W24-V24)))),0) | DC24: =IF(OR(AND(TODAY()>W24,Z24<>1,DB24=1),AND(DB24>='@LeadT_Setting'!$AK$6,Z24<='@LeadT_Setting'!$AK$6),AND(Z24<(DB24-'@LeadT_Setting'!$AJ$6),DB24>Z24,U24>0)),1,0) | DD24: =IF(Z24=1,0,IF(AD24="Engineering",1,IF(AD24="Purchase",2,IF(AD24="Software",3,IF(AD24="Project Management",4,IF(AD24="Manufacturing",5,IF(AD24="Sales",6,IF(AD24="Client",7,0)))))))) | DF24: =Z24*U24 | DG24: =U24 | DH24: =IF(OR(AND(U24>0,TODAY()>=AB24,Z24<80%,NOT(ISBLANK(AB24))),AND(Z24<>1,U24>0,$V24<TODAY(),ISBLANK($Y24))),1,0)
A25: EC | F25: P4 | G25: EC | H25: P4-02 | I25: Pre-Commissioning | P25: 46082 | Q25: 46091 | R25: =S25 | S25: 10 | U25: 10 | V25: =IF(ISBLANK(C32),"",C32) | W25: =IFERROR(IF(S25=0,V25,V25+S25-1),"") | Z25: 1 | AA25: =IFERROR(IF(OR(U25<=0,TODAY()<V25),0,IF(TODAY()>=W25,1,((TODAY()-V25))/((W25-V25)))),0) | AB25: =IFERROR(IF(V25<>"",V25+(W25-V25)*0.8,""),"") | AL25: =Z25 | CY25: =IF(OR(AND(TODAY()>W25,Z25<>1,DB25=1),AND(DB25>='@LeadT_Setting'!$AK$6,Z25<='@LeadT_Setting'!$AK$6),AND(Z25<(DB25-'@LeadT_Setting'!$AI$6),DB25>Z25,U25>0,DB25<'@LeadT_Setting'!$AK$6)),1,0) | CZ25: =IFERROR(AA25*U25,0) | DA25: =IFERROR(Z25*U25,0) | DB25: =IFERROR(IF(OR(U25<=0,TODAY()<V25),0,IF(TODAY()>=W25,1,((TODAY()-V25))/((W25-V25)))),0) | DC25: =IF(OR(AND(TODAY()>W25,Z25<>1,DB25=1),AND(DB25>='@LeadT_Setting'!$AK$6,Z25<='@LeadT_Setting'!$AK$6),AND(Z25<(DB25-'@LeadT_Setting'!$AJ$6),DB25>Z25,U25>0)),1,0) | DD25: =IF(Z25=1,0,IF(AD25="Engineering",1,IF(AD25="Purchase",2,IF(AD25="Software",3,IF(AD25="Project Management",4,IF(AD25="Manufacturing",5,IF(AD25="Sales",6,IF(AD25="Client",7,0)))))))) | DF25: =Z25*U25 | DG25: =U25 | DH25: =IF(OR(AND(U25>0,TODAY()>=AB25,Z25<80%,NOT(ISBLANK(AB25))),AND(Z25<>1,U25>0,$V25<TODAY(),ISBLANK($Y25))),1,0)
A26: EC | F26: P5 | G26: EC | H26: P5-01 | I26: Commissioning | P26: 46091 | Q26: 46106 | R26: =S26 | S26: 16 | U26: 16 | V26: =IF(ISBLANK(C33),"",C33) | W26: =IFERROR(IF(S26=0,V26,V26+S26-1),"") | Z26: 1 | AA26: =IFERROR(IF(OR(U26<=0,TODAY()<V26),0,IF(TODAY()>=W26,1,((TODAY()-V26))/((W26-V26)))),0) | AB26: =IFERROR(IF(V26<>"",V26+(W26-V26)*0.8,""),"") | AL26: =Z26 | CY26: =IF(OR(AND(TODAY()>W26,Z26<>1,DB26=1),AND(DB26>='@LeadT_Setting'!$AK$6,Z26<='@LeadT_Setting'!$AK$6),AND(Z26<(DB26-'@LeadT_Setting'!$AI$6),DB26>Z26,U26>0,DB26<'@LeadT_Setting'!$AK$6)),1,0) | CZ26: =IFERROR(AA26*U26,0) | DA26: =IFERROR(Z26*U26,0) | DB26: =IFERROR(IF(OR(U26<=0,TODAY()<V26),0,IF(TODAY()>=W26,1,((TODAY()-V26))/((W26-V26)))),0) | DC26: =IF(OR(AND(TODAY()>W26,Z26<>1,DB26=1),AND(DB26>='@LeadT_Setting'!$AK$6,Z26<='@LeadT_Setting'!$AK$6),AND(Z26<(DB26-'@LeadT_Setting'!$AJ$6),DB26>Z26,U26>0)),1,0) | DD26: =IF(Z26=1,0,IF(AD26="Engineering",1,IF(AD26="Purchase",2,IF(AD26="Software",3,IF(AD26="Project Management",4,IF(AD26="Manufacturing",5,IF(AD26="Sales",6,IF(AD26="Client",7,0)))))))) | DF26: =Z26*U26 | DG26: =U26 | DH26: =IF(OR(AND(U26>0,TODAY()>=AB26,Z26<80%,NOT(ISBLANK(AB26))),AND(Z26<>1,U26>0,$V26<TODAY(),ISBLANK($Y26))),1,0)
A27: EC | C27: PM Dates | D27: SWE Dates | F27: P5 | G27: EC | H27: P5-02 | I27: Final MOM/Site Report | P27: 46106 | Q27: 46108 | R27: =IFERROR(INDEX('@LeadT_Setting'!$F$6:$J$52,MATCH(I27,'@LeadT_Setting'!$E$6:$E$52,0),MATCH(INDEX('@LeadT_Setting'!$AI$1:$AI$3,MATCH($A27,'@LeadT_Setting'!$AD$1:$AD$3,0),0),'@LeadT_Setting'!$F$1:$J$1,0)),0) | S27: 2 | U27: 2 | V27: =IF(MAX(W23:W26)=0,"",MAX(W23:W26)) | W27: =IFERROR(S27+V27,"") | Z27: 1 | AA27: =IFERROR(IF(OR(U27<=0,TODAY()<V27),0,IF(TODAY()>=W27,1,((TODAY()-V27))/((W27-V27)))),0) | AB27: =IFERROR(IF(V27<>"",V27+(W27-V27)*0.8,""),"") | AL27: =Z27 | CY27: =IF(OR(AND(TODAY()>W27,Z27<>1,DB27=1),AND(DB27>='@LeadT_Setting'!$AK$6,Z27<='@LeadT_Setting'!$AK$6),AND(Z27<(DB27-'@LeadT_Setting'!$AI$6),DB27>Z27,U27>0,DB27<'@LeadT_Setting'!$AK$6)),1,0) | CZ27: =IFERROR(AA27*U27,0) | DA27: =IFERROR(Z27*U27,0) | DB27: =IFERROR(IF(OR(U27<=0,TODAY()<V27),0,IF(TODAY()>=W27,1,((TODAY()-V27))/((W27-V27)))),0) | DC27: =IF(OR(AND(TODAY()>W27,Z27<>1,DB27=1),AND(DB27>='@LeadT_Setting'!$AK$6,Z27<='@LeadT_Setting'!$AK$6),AND(Z27<(DB27-'@LeadT_Setting'!$AJ$6),DB27>Z27,U27>0)),1,0) | DD27: =IF(Z27=1,0,IF(AD27="Engineering",1,IF(AD27="Purchase",2,IF(AD27="Software",3,IF(AD27="Project Management",4,IF(AD27="Manufacturing",5,IF(AD27="Sales",6,IF(AD27="Client",7,0)))))))) | DF27: =Z27*U27 | DG27: =U27 | DH27: =IF(OR(AND(U27>0,TODAY()>=AB27,Z27<80%,NOT(ISBLANK(AB27))),AND(Z27<>1,U27>0,$V27<TODAY(),ISBLANK($Y27))),1,0)
A28: SW | B28: Internal KOM | C28: 44354 | D28: =V10 | F28: P5 | G28: SW | H28: P5-03 | I28: As Comm. Doc (SW) | P28: 46106 | Q28: 46108 | R28: =IFERROR(INDEX('@LeadT_Setting'!$F$6:$J$52,MATCH(I28,'@LeadT_Setting'!$E$6:$E$52,0),MATCH(INDEX('@LeadT_Setting'!$AI$1:$AI$3,MATCH($A28,'@LeadT_Setting'!$AD$1:$AD$3,0),0),'@LeadT_Setting'!$F$1:$J$1,0)),0) | S28: 0 | U28: 0.001 | V28: =IF(S28>0,W27+1,V27) | W28: =IFERROR(IF(S28=0,W27,V28+S28-1),"") | Z28: 1 | AA28: =IFERROR(IF(OR(U28<=0,TODAY()<V28),0,IF(TODAY()>=W28,1,((TODAY()-V28))/((W28-V28)))),0) | AB28: =IFERROR(IF(V28<>"",V28+(W28-V28)*0.8,""),"") | AL28: =Z28 | CY28: =IF(OR(AND(TODAY()>W28,Z28<>1,DB28=1),AND(DB28>='@LeadT_Setting'!$AK$6,Z28<='@LeadT_Setting'!$AK$6),AND(Z28<(DB28-'@LeadT_Setting'!$AI$6),DB28>Z28,U28>0,DB28<'@LeadT_Setting'!$AK$6)),1,0) | CZ28: =IFERROR(AA28*U28,0) | DA28: =IFERROR(Z28*U28,0) | DB28: =IFERROR(IF(OR(U28<=0,TODAY()<V28),0,IF(TODAY()>=W28,1,((TODAY()-V28))/((W28-V28)))),0) | DC28: =IF(OR(AND(TODAY()>W28,Z28<>1,DB28=1),AND(DB28>='@LeadT_Setting'!$AK$6,Z28<='@LeadT_Setting'!$AK$6),AND(Z28<(DB28-'@LeadT_Setting'!$AJ$6),DB28>Z28,U28>0)),1,0) | DD28: =IF(Z28=1,0,IF(AD28="Engineering",1,IF(AD28="Purchase",2,IF(AD28="Software",3,IF(AD28="Project Management",4,IF(AD28="Manufacturing",5,IF(AD28="Sales",6,IF(AD28="Client",7,0)))))))) | DH28: =IF(OR(AND(U28>0,TODAY()>=AB28,Z28<80%,NOT(ISBLANK(AB28))),AND(Z28<>1,U28>0,$V28<TODAY(),ISBLANK($Y28))),1,0)
A29: EC | B29: SW Input | C29: 45085 | D29: =V11 | F29: P5 | G29: EC | H29: P5-04 | I29: Post Comm. Support | P29: 46109 | Q29: 46110 | R29: =IFERROR(INDEX('@LeadT_Setting'!$F$6:$J$52,MATCH(I29,'@LeadT_Setting'!$E$6:$E$52,0),MATCH(INDEX('@LeadT_Setting'!$AI$1:$AI$3,MATCH($A29,'@LeadT_Setting'!$AD$1:$AD$3,0),0),'@LeadT_Setting'!$F$1:$J$1,0)),0) | S29: 2 | U29: 2 | V29: =IF(S29>0,W28+1,V28) | W29: =IFERROR(IF(S29=0,W28,V29+S29-1),"") | Z29: 1 | AA29: =IFERROR(IF(OR(U29<=0,TODAY()<V29),0,IF(TODAY()>=W29,1,((TODAY()-V29))/((W29-V29)))),0) | AB29: =IFERROR(IF(V29<>"",V29+(W29-V29)*0.8,""),"") | AL29: =Z29 | CY29: =IF(OR(AND(TODAY()>W29,Z29<>1,DB29=1),AND(DB29>='@LeadT_Setting'!$AK$6,Z29<='@LeadT_Setting'!$AK$6),AND(Z29<(DB29-'@LeadT_Setting'!$AI$6),DB29>Z29,U29>0,DB29<'@LeadT_Setting'!$AK$6)),1,0) | CZ29: =IFERROR(AA29*U29,0) | DA29: =IFERROR(Z29*U29,0) | DB29: =IFERROR(IF(OR(U29<=0,TODAY()<V29),0,IF(TODAY()>=W29,1,((TODAY()-V29))/((W29-V29)))),0) | DC29: =IF(OR(AND(TODAY()>W29,Z29<>1,DB29=1),AND(DB29>='@LeadT_Setting'!$AK$6,Z29<='@LeadT_Setting'!$AK$6),AND(Z29<(DB29-'@LeadT_Setting'!$AJ$6),DB29>Z29,U29>0)),1,0) | DD29: =IF(Z29=1,0,IF(AD29="Engineering",1,IF(AD29="Purchase",2,IF(AD29="Software",3,IF(AD29="Project Management",4,IF(AD29="Manufacturing",5,IF(AD29="Sales",6,IF(AD29="Client",7,0)))))))) | DF29: =Z29*U29 | DG29: =U29 | DH29: =IF(OR(AND(U29>0,TODAY()>=AB29,Z29<80%,NOT(ISBLANK(AB29))),AND(Z29<>1,U29>0,$V29<TODAY(),ISBLANK($Y29))),1,0)
A30: SW | B30: SW FAT | C30: 45140 | D30: =V22 | F30: P5 | G30: SW | H30: P5-05 | I30: Project Closure | P30: 46109 | Q30: 46110 | R30: =IFERROR(INDEX('@LeadT_Setting'!$F$6:$J$52,MATCH(I30,'@LeadT_Setting'!$E$6:$E$52,0),MATCH(INDEX('@LeadT_Setting'!$AI$1:$AI$3,MATCH($A30,'@LeadT_Setting'!$AD$1:$AD$3,0),0),'@LeadT_Setting'!$F$1:$J$1,0)),0) | S30: 0 | U30: 0.001 | V30: =IF(S30>0,W29+1,V29) | W30: =IF(S30=0,W29,V30+S30-1) | Z30: 1 | AA30: =IFERROR(IF(OR(U30<=0,TODAY()<V30),0,IF(TODAY()>=W30,1,((TODAY()-V30))/((W30-V30)))),0) | AB30: =IFERROR(IF(V30<>"",V30+(W30-V30)*0.8,""),"") | AL30: =Z30 | CY30: =IF(OR(AND(TODAY()>W30,Z30<>1,DB30=1),AND(DB30>='@LeadT_Setting'!$AK$6,Z30<='@LeadT_Setting'!$AK$6),AND(Z30<(DB30-'@LeadT_Setting'!$AI$6),DB30>Z30,U30>0,DB30<'@LeadT_Setting'!$AK$6)),1,0) | CZ30: =IFERROR(AA30*U30,0) | DA30: =IFERROR(Z30*U30,0) | DB30: =IFERROR(IF(OR(U30<=0,TODAY()<V30),0,IF(TODAY()>=W30,1,((TODAY()-V30))/((W30-V30)))),0) | DC30: =IF(OR(AND(TODAY()>W30,Z30<>1,DB30=1),AND(DB30>='@LeadT_Setting'!$AK$6,Z30<='@LeadT_Setting'!$AK$6),AND(Z30<(DB30-'@LeadT_Setting'!$AJ$6),DB30>Z30,U30>0)),1,0) | DD30: =IF(Z30=1,0,IF(AD30="Engineering",1,IF(AD30="Purchase",2,IF(AD30="Software",3,IF(AD30="Project Management",4,IF(AD30="Manufacturing",5,IF(AD30="Sales",6,IF(AD30="Client",7,0)))))))) | DH30: =IF(OR(AND(U30>0,TODAY()>=AB30,Z30<80%,NOT(ISBLANK(AB30))),AND(Z30<>1,U30>0,$V30<TODAY(),ISBLANK($Y30))),1,0)
B31: Install | D31: =V24 | AL31: =Z31 | CY31: =IF(OR(AND(TODAY()>W31,Z31<>1,DB31=1),AND(DB31>='@LeadT_Setting'!$AK$6,Z31<='@LeadT_Setting'!$AK$6),AND(Z31<(DB31-'@LeadT_Setting'!$AI$6),DB31>Z31,U31>0,DB31<'@LeadT_Setting'!$AK$6)),1,0) | CZ31: =IFERROR(AA31*U31,0) | DA31: =IFERROR(Z31*U31,0) | DB31: =IFERROR(IF(OR(U31<=0,TODAY()<V31),0,IF(TODAY()>=W31,1,((TODAY()-V31))/((W31-V31)))),0) | DC31: =IF(OR(AND(TODAY()>W31,Z31<>1,DB31=1),AND(DB31>='@LeadT_Setting'!$AK$6,Z31<='@LeadT_Setting'!$AK$6),AND(Z31<(DB31-'@LeadT_Setting'!$AJ$6),DB31>Z31,U31>0)),1,0) | DD31: =IF(Z31=1,0,IF(AD31="Engineering",1,IF(AD31="Purchase",2,IF(AD31="Software",3,IF(AD31="Project Management",4,IF(AD31="Manufacturing",5,IF(AD31="Sales",6,IF(AD31="Client",7,0)))))))) | DF31: =Z31*U31 | DH31: =IF(OR(AND(U31>0,TODAY()>=AB31,Z31<80%,NOT(ISBLANK(AB31))),AND(Z31<>1,U31>0,$V31<TODAY(),ISBLANK($Y31))),1,0)
B32: PreComm. | C32: 46082 | D32: =V25 | AL32: =Z32 | CY32: =IF(OR(AND(TODAY()>W32,Z32<>1,DB32=1),AND(DB32>='@LeadT_Setting'!$AK$6,Z32<='@LeadT_Setting'!$AK$6),AND(Z32<(DB32-'@LeadT_Setting'!$AI$6),DB32>Z32,U32>0,DB32<'@LeadT_Setting'!$AK$6)),1,0) | CZ32: =IFERROR(AA32*U32,0) | DA32: =IFERROR(Z32*U32,0) | DB32: =IFERROR(IF(OR(U32<=0,TODAY()<V32),0,IF(TODAY()>=W32,1,((TODAY()-V32))/((W32-V32)))),0) | DC32: =IF(OR(AND(TODAY()>W32,Z32<>1,DB32=1),AND(DB32>='@LeadT_Setting'!$AK$6,Z32<='@LeadT_Setting'!$AK$6),AND(Z32<(DB32-'@LeadT_Setting'!$AJ$6),DB32>Z32,U32>0)),1,0) | DD32: =IF(Z32=1,0,IF(AD32="Engineering",1,IF(AD32="Purchase",2,IF(AD32="Software",3,IF(AD32="Project Management",4,IF(AD32="Manufacturing",5,IF(AD32="Sales",6,IF(AD32="Client",7,0)))))))) | DF32: =Z32*U32 | DH32: =IF(OR(AND(U32>0,TODAY()>=AB32,Z32<80%,NOT(ISBLANK(AB32))),AND(Z32<>1,U32>0,$V32<TODAY(),ISBLANK($Y32))),1,0)
B33: Comm. | C33: 46091 | D33: =V26 | AL33: =Z33 | CY33: =IF(OR(AND(TODAY()>W33,Z33<>1,DB33=1),AND(DB33>='@LeadT_Setting'!$AK$6,Z33<='@LeadT_Setting'!$AK$6),AND(Z33<(DB33-'@LeadT_Setting'!$AI$6),DB33>Z33,U33>0,DB33<'@LeadT_Setting'!$AK$6)),1,0) | CZ33: =IFERROR(AA33*U33,0) | DA33: =IFERROR(Z33*U33,0) | DB33: =IFERROR(IF(OR(U33<=0,TODAY()<V33),0,IF(TODAY()>=W33,1,((TODAY()-V33))/((W33-V33)))),0) | DC33: =IF(OR(AND(TODAY()>W33,Z33<>1,DB33=1),AND(DB33>='@LeadT_Setting'!$AK$6,Z33<='@LeadT_Setting'!$AK$6),AND(Z33<(DB33-'@LeadT_Setting'!$AJ$6),DB33>Z33,U33>0)),1,0) | DD33: =IF(Z33=1,0,IF(AD33="Engineering",1,IF(AD33="Purchase",2,IF(AD33="Software",3,IF(AD33="Project Management",4,IF(AD33="Manufacturing",5,IF(AD33="Sales",6,IF(AD33="Client",7,0)))))))) | DF33: =Z33*U33 | DH33: =IF(OR(AND(U33>0,TODAY()>=AB33,Z33<80%,NOT(ISBLANK(AB33))),AND(Z33<>1,U33>0,$V33<TODAY(),ISBLANK($Y33))),1,0)
AL34: =Z34 | CY34: =IF(OR(AND(TODAY()>W34,Z34<>1,DB34=1),AND(DB34>='@LeadT_Setting'!$AK$6,Z34<='@LeadT_Setting'!$AK$6),AND(Z34<(DB34-'@LeadT_Setting'!$AI$6),DB34>Z34,U34>0,DB34<'@LeadT_Setting'!$AK$6)),1,0) | CZ34: =IFERROR(AA34*U34,0) | DA34: =IFERROR(Z34*U34,0) | DB34: =IFERROR(IF(OR(U34<=0,TODAY()<V34),0,IF(TODAY()>=W34,1,((TODAY()-V34))/((W34-V34)))),0) | DC34: =IF(OR(AND(TODAY()>W34,Z34<>1,DB34=1),AND(DB34>='@LeadT_Setting'!$AK$6,Z34<='@LeadT_Setting'!$AK$6),AND(Z34<(DB34-'@LeadT_Setting'!$AJ$6),DB34>Z34,U34>0)),1,0) | DD34: =IF(Z34=1,0,IF(AD34="Engineering",1,IF(AD34="Purchase",2,IF(AD34="Software",3,IF(AD34="Project Management",4,IF(AD34="Manufacturing",5,IF(AD34="Sales",6,IF(AD34="Client",7,0)))))))) | DF34: =Z34*U34 | DH34: =IF(OR(AND(U34>0,TODAY()>=AB34,Z34<80%,NOT(ISBLANK(AB34))),AND(Z34<>1,U34>0,$V34<TODAY(),ISBLANK($Y34))),1,0)
B35: Stake Holders | AL35: =Z35 | CY35: =IF(OR(AND(TODAY()>W35,Z35<>1,DB35=1),AND(DB35>='@LeadT_Setting'!$AK$6,Z35<='@LeadT_Setting'!$AK$6),AND(Z35<(DB35-'@LeadT_Setting'!$AI$6),DB35>Z35,U35>0,DB35<'@LeadT_Setting'!$AK$6)),1,0) | CZ35: =IFERROR(AA35*U35,0) | DA35: =IFERROR(Z35*U35,0) | DB35: =IFERROR(IF(OR(U35<=0,TODAY()<V35),0,IF(TODAY()>=W35,1,((TODAY()-V35))/((W35-V35)))),0) | DC35: =IF(OR(AND(TODAY()>W35,Z35<>1,DB35=1),AND(DB35>='@LeadT_Setting'!$AK$6,Z35<='@LeadT_Setting'!$AK$6),AND(Z35<(DB35-'@LeadT_Setting'!$AJ$6),DB35>Z35,U35>0)),1,0) | DD35: =IF(Z35=1,0,IF(AD35="Engineering",1,IF(AD35="Purchase",2,IF(AD35="Software",3,IF(AD35="Project Management",4,IF(AD35="Manufacturing",5,IF(AD35="Sales",6,IF(AD35="Client",7,0)))))))) | DF35: =Z35*U35 | DH35: =IF(OR(AND(U35>0,TODAY()>=AB35,Z35<80%,NOT(ISBLANK(AB35))),AND(Z35<>1,U35>0,$V35<TODAY(),ISBLANK($Y35))),1,0)
B36: Sales | C36: GS | AL36: =Z36 | CY36: =IF(OR(AND(TODAY()>W36,Z36<>1,DB36=1),AND(DB36>='@LeadT_Setting'!$AK$6,Z36<='@LeadT_Setting'!$AK$6),AND(Z36<(DB36-'@LeadT_Setting'!$AI$6),DB36>Z36,U36>0,DB36<'@LeadT_Setting'!$AK$6)),1,0) | CZ36: =IFERROR(AA36*U36,0) | DA36: =IFERROR(Z36*U36,0) | DB36: =IFERROR(IF(OR(U36<=0,TODAY()<V36),0,IF(TODAY()>=W36,1,((TODAY()-V36))/((W36-V36)))),0) | DC36: =IF(OR(AND(TODAY()>W36,Z36<>1,DB36=1),AND(DB36>='@LeadT_Setting'!$AK$6,Z36<='@LeadT_Setting'!$AK$6),AND(Z36<(DB36-'@LeadT_Setting'!$AJ$6),DB36>Z36,U36>0)),1,0) | DD36: =IF(Z36=1,0,IF(AD36="Engineering",1,IF(AD36="Purchase",2,IF(AD36="Software",3,IF(AD36="Project Management",4,IF(AD36="Manufacturing",5,IF(AD36="Sales",6,IF(AD36="Client",7,0)))))))) | DF36: =Z36*U36 | DH36: =IF(OR(AND(U36>0,TODAY()>=AB36,Z36<80%,NOT(ISBLANK(AB36))),AND(Z36<>1,U36>0,$V36<TODAY(),ISBLANK($Y36))),1,0)
B37: PM | C37: NSK | AL37: =Z37 | CY37: =IF(OR(AND(TODAY()>W37,Z37<>1,DB37=1),AND(DB37>='@LeadT_Setting'!$AK$6,Z37<='@LeadT_Setting'!$AK$6),AND(Z37<(DB37-'@LeadT_Setting'!$AI$6),DB37>Z37,U37>0,DB37<'@LeadT_Setting'!$AK$6)),1,0) | CZ37: =IFERROR(AA37*U37,0) | DA37: =IFERROR(Z37*U37,0) | DB37: =IFERROR(IF(OR(U37<=0,TODAY()<V37),0,IF(TODAY()>=W37,1,((TODAY()-V37))/((W37-V37)))),0) | DC37: =IF(OR(AND(TODAY()>W37,Z37<>1,DB37=1),AND(DB37>='@LeadT_Setting'!$AK$6,Z37<='@LeadT_Setting'!$AK$6),AND(Z37<(DB37-'@LeadT_Setting'!$AJ$6),DB37>Z37,U37>0)),1,0) | DD37: =IF(Z37=1,0,IF(AD37="Engineering",1,IF(AD37="Purchase",2,IF(AD37="Software",3,IF(AD37="Project Management",4,IF(AD37="Manufacturing",5,IF(AD37="Sales",6,IF(AD37="Client",7,0)))))))) | DF37: =Z37*U37 | DH37: =IF(OR(AND(U37>0,TODAY()>=AB37,Z37<80%,NOT(ISBLANK(AB37))),AND(Z37<>1,U37>0,$V37<TODAY(),ISBLANK($Y37))),1,0)
B38: HW | C38: KSP | AL38: =Z38 | CY38: =IF(OR(AND(TODAY()>W38,Z38<>1,DB38=1),AND(DB38>='@LeadT_Setting'!$AK$6,Z38<='@LeadT_Setting'!$AK$6),AND(Z38<(DB38-'@LeadT_Setting'!$AI$6),DB38>Z38,U38>0,DB38<'@LeadT_Setting'!$AK$6)),1,0) | CZ38: =IFERROR(AA38*U38,0) | DA38: =IFERROR(Z38*U38,0) | DB38: =IFERROR(IF(OR(U38<=0,TODAY()<V38),0,IF(TODAY()>=W38,1,((TODAY()-V38))/((W38-V38)))),0) | DC38: =IF(OR(AND(TODAY()>W38,Z38<>1,DB38=1),AND(DB38>='@LeadT_Setting'!$AK$6,Z38<='@LeadT_Setting'!$AK$6),AND(Z38<(DB38-'@LeadT_Setting'!$AJ$6),DB38>Z38,U38>0)),1,0) | DD38: =IF(Z38=1,0,IF(AD38="Engineering",1,IF(AD38="Purchase",2,IF(AD38="Software",3,IF(AD38="Project Management",4,IF(AD38="Manufacturing",5,IF(AD38="Sales",6,IF(AD38="Client",7,0)))))))) | DF38: =Z38*U38 | DH38: =IF(OR(AND(U38>0,TODAY()>=AB38,Z38<80%,NOT(ISBLANK(AB38))),AND(Z38<>1,U38>0,$V38<TODAY(),ISBLANK($Y38))),1,0)
B39: BYR | C39: RVL | AL39: =Z39 | CY39: =IF(OR(AND(TODAY()>W39,Z39<>1,DB39=1),AND(DB39>='@LeadT_Setting'!$AK$6,Z39<='@LeadT_Setting'!$AK$6),AND(Z39<(DB39-'@LeadT_Setting'!$AI$6),DB39>Z39,U39>0,DB39<'@LeadT_Setting'!$AK$6)),1,0) | CZ39: =IFERROR(AA39*U39,0) | DA39: =IFERROR(Z39*U39,0) | DB39: =IFERROR(IF(OR(U39<=0,TODAY()<V39),0,IF(TODAY()>=W39,1,((TODAY()-V39))/((W39-V39)))),0) | DC39: =IF(OR(AND(TODAY()>W39,Z39<>1,DB39=1),AND(DB39>='@LeadT_Setting'!$AK$6,Z39<='@LeadT_Setting'!$AK$6),AND(Z39<(DB39-'@LeadT_Setting'!$AJ$6),DB39>Z39,U39>0)),1,0) | DD39: =IF(Z39=1,0,IF(AD39="Engineering",1,IF(AD39="Purchase",2,IF(AD39="Software",3,IF(AD39="Project Management",4,IF(AD39="Manufacturing",5,IF(AD39="Sales",6,IF(AD39="Client",7,0)))))))) | DF39: =Z39*U39 | DH39: =IF(OR(AND(U39>0,TODAY()>=AB39,Z39<80%,NOT(ISBLANK(AB39))),AND(Z39<>1,U39>0,$V39<TODAY(),ISBLANK($Y39))),1,0)
B40: MFG | C40: SBP | AL40: =Z40 | CY40: =IF(OR(AND(TODAY()>W40,Z40<>1,DB40=1),AND(DB40>='@LeadT_Setting'!$AK$6,Z40<='@LeadT_Setting'!$AK$6),AND(Z40<(DB40-'@LeadT_Setting'!$AI$6),DB40>Z40,U40>0,DB40<'@LeadT_Setting'!$AK$6)),1,0) | CZ40: =IFERROR(AA40*U40,0) | DA40: =IFERROR(Z40*U40,0) | DB40: =IFERROR(IF(OR(U40<=0,TODAY()<V40),0,IF(TODAY()>=W40,1,((TODAY()-V40))/((W40-V40)))),0) | DC40: =IF(OR(AND(TODAY()>W40,Z40<>1,DB40=1),AND(DB40>='@LeadT_Setting'!$AK$6,Z40<='@LeadT_Setting'!$AK$6),AND(Z40<(DB40-'@LeadT_Setting'!$AJ$6),DB40>Z40,U40>0)),1,0) | DD40: =IF(Z40=1,0,IF(AD40="Engineering",1,IF(AD40="Purchase",2,IF(AD40="Software",3,IF(AD40="Project Management",4,IF(AD40="Manufacturing",5,IF(AD40="Sales",6,IF(AD40="Client",7,0)))))))) | DF40: =Z40*U40 | DH40: =IF(OR(AND(U40>0,TODAY()>=AB40,Z40<80%,NOT(ISBLANK(AB40))),AND(Z40<>1,U40>0,$V40<TODAY(),ISBLANK($Y40))),1,0)
...

Sheet AmendmentIndex
A3: Amendment Index
C6: Sales OR | D6: =PrjSch!D1
C7: Section | D7: =PrjSch!D13
C8: Customer Name | D8: =PrjSch!D9
F9: =SUM(F11:F30)
B10: Dwg No | C10: Rev | D10: Amendment Description | E10: Mfg Efforts Description | F10: Hours | G10: Date Raised | H10: Date Closed
A57: EndRow | B57: EndRow | C57: EndRow | D57: EndRow | E57: EndRow | F57: EndRow | G57: EndRow | H57: EndRow | I57: EndRow

Sheet @LeadT_Setting
F1: Small | G1: Medium | H1: Large | I1: Very Large | J1: Non-Standard | AC1: Days | AD1: HW | AE1: 4 | AF1: 10 | AG1: 50 | AH1: 75 | AI1: =IF(PrjSch!$D17>$AH1,"Non-Standard",IF(PrjSch!$D17>$AG1,"Very Large",IF(PrjSch!$D17>$AF1,"Large",IF(PrjSch!$D17>$AE1,"Medium",IF(PrjSch!$D17>0,"Small","-")))))
D2: In | E2: Clearance to Mfg | F2: =(F6+F7+F8+F9+F10+F12)/7 | G2: =(G6+G7+G8+G9+G10+G12)/7 | H2: =(H6+H7+H8+H9+H10+H12)/7 | I2: =(I6+I7+I8+I9+I10+I12)/7 | J2: =(J6+J7+J8+J9+J10+J12)/7 | Z2: =F2/0.85 | AC2: No. | AD2: MFG | AE2: 5 | AF2: 15 | AG2: 25 | AH2: 50 | AI2: =IF(PrjSch!$D17>$AH2,"Non-Standard",IF(PrjSch!$D17>$AG2,"Very Large",IF(PrjSch!$D17>$AF2,"Large",IF(PrjSch!$D17>$AE2,"Medium",IF(PrjSch!$D17>0,"Small","-"))))) | AJ2: =COUNTA(A9:A260)
D3: Weeks | E3: Clearance to Dispatch | F3: =(F6+F7+F21+F22+F23+F25+F26+F27+F28+F30+F32+F33+F34)/7 | G3: =(G6+G7+G21+G22+G23+G25+G26+G27+G28+G30+G32+G33+G34)/7 | H3: =(H6+H7+H21+H22+H23+H25+H26+H27+H28+H30+H32+H33+H34)/7 | I3: =(I6+I7+I21+I22+I23+I25+I26+I27+I28+I30+I32+I33+I34)/7 | J3: =(J6+J7+J21+J22+J23+J25+J26+J27+J28+J30+J32+J33+J34)/7 | AC3: Days | AD3: SW | AE3: 14 | AF3: 60 | AG3: 100 | AH3: 150 | AI3: =IF(PrjSch!$D17>$AH3,"Non-Standard",IF(PrjSch!$D17>$AG3,"Very Large",IF(PrjSch!$D17>$AF3,"Large",IF(PrjSch!$D17>$AE3,"Medium",IF(PrjSch!$D17>0,"Small","-")))))
A4: Sec. | B4: Ph | C4: TFO | D4: Phase ID | E4: Task Description | F4: Ref Lead Time | G4: Ref Lead Time | H4: Ref Lead Time | I4: Ref Lead Time | J4: Ref Lead Time | Z4: PM | AA4: SW | AB4: HW | AE4: Medium | AF4: Large | AG4: Vlarge | AH4: Non-Standard | DS4: Delay Reason | DT4: Delay Code
A5: FL | B5: FL | C5: FL | D5: FL | E5: FL | F5: FL | G5: FL | H5: FL | I5: FL | J5: FL | Z5: Schedule | AI5: PM Alarm | AJ5: PL Alarm | AK5: Default Alarm % | AL5: Payment Status | AM5: Mfg LOC | AN5: Warranty | AO5: Warranty Meaning | DS5: FL | DT5: FL
B6: P1 | C6: SW | D6: P1-01 | E6: Project Scheduling | F6: 0 | G6: 1 | H6: 1 | I6: 2 | J6: 8 | Y6: Supervisor | Z6: Run | AI6: 0.2 | AJ6: 0.1 | AK6: 0.8 | AN6: Standard | AO6: 24 months from the date of commissioning or 30 months from the date of supply, whichever is earlier. Faulty material to be delivered at our premises and replacement to be collected from our premises. | DR6: Legend | DS6: Mfg Manpower shortage | DT6: D001
B7: P1 | C7: SW | D7: P1-02 | E7: Internal KOM | F7: 0 | G7: 1 | H7: 1 | I7: 2 | J7: 16 | Y7: Supervisor | Z7: Hold | AL7: Received | AM7: GON | DR7: Dxxx : Delay | DS7: Mfg Manpower engaged | DT7: D002
B8: P1 | C8: SW | D8: P1-03 | E8: SW I/P Collection | F8: 3 | G8: 4 | H8: 5 | I8: 7 | J8: 15 | Y8: Fitter | Z8: Closed | AM8: DUB | AT8: SW | AU8: SW | AV8: SW | AW8: SW | AX8: SW | AY8: SW | AZ8: SW | BA8: SW | BB8: SW | BC8: SW | BD8: SW | BE8: SW | BF8: SW | BG8: SW | BH8: SW | BI8: EC | BJ8: EC | BK8: EC | BL8: EC | BM8: SW | BN8: EC | BO8: SW | DR8: Exxx: Error | DS8: Sales Material available <85% | DT8: S001
B9: P2 | C9: SW | D9: P2-01 | E9: SW Design Preparation | F9: 2 | G9: 4 | H9: 6 | I9: 8 | J9: 12 | Y9: Electrician | AT9: Project Scheduling | AU9: Internal KOM | AV9: SW I/P Collection | AW9: SW Design Preparation | AX9: SW Design Validation | AY9: SW Documents Submission | AZ9: SW Documents Approval | BA9: Drive SW | BB9: PLC SW | BC9: HMI/SCADA | BD9: Report | BE9: Internal testing | BF9: SW FAT Call with Test Report | BG9: SW FAT | BH9: SW FAT Compliance | BI9: Installation | BJ9: Pre-Commissioning | BK9: Commissioning | BL9: Final MOM/Site Report | BM9: As Comm. Doc (SW) | BN9: Post Comm. Support | BO9: Project Closure | DM9: Engg | DN9: RED | DO9: 1 | DP9: Engineering | DQ9: =DP9&","&DP10&","&DP11&","&DP12&","&DP13 | DR9: Sxxx: Supply chain | DS9: Sales main material shortfall | DT9: S002
B10: P2 | C10: SW | D10: P2-02 | E10: SW Design Validation | F10: 1 | G10: 1 | H10: 1 | I10: 3 | J10: 5 | Y10: Electrician | AM10: =PrjSch!D15 | AN10: =INDEX(AN12:AN20,MATCH(AM10,PackgingType,0)) | AP10: SrNo | AQ10: SWE Status | AR10: =IFERROR(INDEX(AR11:AR27,MATCH(AS10,AS11:AS27,0)),AR27) | AS10: 0 | DM10: Pur/Buyr | DN10: ORANGE | DO10: 2 | DP10: Purchase | DS10: Vendor sent wrong material | DT10: S003
B11: P2 | C11: SW | D11: P2-03 | E11: SW Documents Submission | F11: 1 | G11: 1 | H11: 1 | I11: 3 | J11: 8 | Y11: Electrician | AJ11: HW Efforts | AK11: SW Efforts | AL11: No of Panels | AM11: Panel Packaging Type | AN11: Lead Time | AP11: 1 | AQ11: Init | AR11: Init | AS11: =IF(PRODUCT(AT11:CN11)=1,1,0) | AU11: =INDEX(PrjSch!$Z:$Z,MATCH(AU$9,PrjSch!$I:$I,0)) | DM11: Softw | DN11: LitBLUE | DO11: 3 | DP11: Software | DS11: Material Quality cocnern | DT11: S004
B12: P3 | C12: SW | D12: P3-01 | E12: SW Documents Approval | F12: 4 | G12: 6 | H12: 8 | I12: 10 | J12: 10 | Y12: Engineer | AI12: Small | AJ12: 1,4 | AK12: 1,14 | AL12: 1,5 | AM12: Client's Scope | AN12: 0 | AP12: 2 | AQ12: SWInput | AR12: SWInput | AS12: =IF(PRODUCT(AT12:CN12)=1,1,0) | AV12: =INDEX(PrjSch!$Z:$Z,MATCH(AV$9,PrjSch!$I:$I,0)) | DM12: PM | DN12: BLUE | DO12: 4 | DP12: Project Management | DS12: Wrong Material ordered | DT12: E001
B13: P3 | C13: SW | D13: P3-02 | E13: Drive SW | F13: 21 | G13: 35 | H13: 63 | I13: 75 | J13: 90 | Y13: Engineer | AI13: Medium | AJ13: 5,10 | AK13: 15,60 | AL13: 6,15 | AM13: Domestic Crate Econo | AN13: 1 | AP13: 3 | AQ13: Design | AR13: Design | AS13: =IF(PRODUCT(AT13:CN13)=1,1,0) | AW13: =INDEX(PrjSch!$Z:$Z,MATCH(AW$9,PrjSch!$I:$I,0)) | AX13: =INDEX(PrjSch!$Z:$Z,MATCH(AX$9,PrjSch!$I:$I,0)) | DM13: Mfg | DN13: BROWN | DO13: 5 | DP13: Manufacturing | DS13: Short of material ordering | DT13: E002
B14: P3 | C14: SW | D14: P3-03 | E14: PLC SW | Y14: Supervisor | AI14: Large | AJ14: 11,50 | AK14: 61,100 | AL14: 16,25 | AM14: Domestic Crate Std | AN14: 1 | AP14: 4 | AQ14: SWDocs | AR14: SWDocs | AS14: =IF(PRODUCT(AT14:CN14)=1,1,0) | AY14: =INDEX(PrjSch!$Z:$Z,MATCH(AY$9,PrjSch!$I:$I,0)) | DM14: Sales | DN14: CYAN | DO14: 6 | DP14: Sales | DS14: WD corrections | DT14: E003
B15: P3 | C15: SW | D15: P3-04 | E15: HMI/SCADA | Y15: Engineer | AI15: Very Large | AJ15: 51,75 | AK15: 101,150 | AL15: 26,50 | AM15: Domestic Box Wood | AN15: 1 | AP15: 5 | AQ15: SWDocsAprv | AR15: SWDocsAprv | AS15: =IF(PRODUCT(AT15:CN15)=1,1,0) | AZ15: =INDEX(PrjSch!$Z:$Z,MATCH(AZ$9,PrjSch!$I:$I,0)) | DM15: Client | DN15: PURPLE | DO15: 7 | DP15: Client | DS15: Project Priority changed | DT15: D003
B16: P3 | C16: SW | D16: P3-05 | E16: Report | Y16: Engineer | AI16: Non-Standard | AJ16: 76 | AK16: 151 | AL16: 51 | AM16: Domestic Box Ply+Wood | AN16: 2 | AP16: 6 | AQ16: DriveSW | AR16: DriveSW | AS16: =IF(PRODUCT(AT16:CN16)=1,1,0) | BA16: =INDEX(PrjSch!$Z:$Z,MATCH(BA$9,PrjSch!$I:$I,0)) | DS16: WD changed | DT16: D004
B17: P3 | C17: SW | D17: P3-06 | E17: Internal testing | Y17: Supervisor | AM17: Domestic Base Econo | AN17: 2 | AP17: 7 | AQ17: PLCSW | AR17: PLCSW | AS17: =IF(PRODUCT(AT17:CN17)=1,1,0) | BB17: =INDEX(PrjSch!$Z:$Z,MATCH(BB$9,PrjSch!$I:$I,0)) | DS17: Mechanical rework | DT17: D005
B18: P3 | C18: SW | D18: P3-07 | E18: SW FAT Call with Test Report | F18: 4 | G18: 5 | H18: 4 | I18: 4 | J18: 4 | Y18: Fitter | AM18: Export Crate Econo | AN18: 2 | AP18: 8 | AQ18: SCADA | AR18: SCADA | AS18: =IF(PRODUCT(AT18:CN18)=1,1,0) | BC18: =INDEX(PrjSch!$Z:$Z,MATCH(BC$9,PrjSch!$I:$I,0)) | DS18: Electrical rework | DT18: D006
B19: P3 | C19: SW | D19: P3-08 | E19: SW FAT | F19: 2 | G19: 2 | H19: 2 | I19: 6 | J19: 8 | Y19: Supervisor | AM19: Export Box Std | AN19: 3 | AP19: 9 | AQ19: Report | AR19: Report | AS19: =IF(PRODUCT(AT19:CN19)=1,1,0) | BD19: =INDEX(PrjSch!$Z:$Z,MATCH(BD$9,PrjSch!$I:$I,0)) | DS19: Configuration rework | DT19: D007
B20: P4 | C20: SW | D20: P4-01 | E20: SW FAT Compliance | F20: 2 | G20: 2 | H20: 2 | I20: 4 | J20: 4 | Y20: Engineer | AM20: Export Box Seaworthy | AN20: 4 | AP20: 10 | AQ20: InternalTest | AR20: InternalTest | AS20: =IF(PRODUCT(AT20:CN20)=1,1,0) | BE20: =INDEX(PrjSch!$Z:$Z,MATCH(BE$9,PrjSch!$I:$I,0)) | DS20: PLC/HMI program concerns | DT20: D008
B21: P4 | C21: EC | D21: P4-02 | E21: Installation | F21: 0 | G21: 0 | H21: 0 | I21: 0 | J21: 0 | Y21: Supervisor | AP21: 11 | AQ21: SWFAT | AR21: SWFAT | AS21: =IF(PRODUCT(AT21:CN21)=1,1,0) | BF21: =INDEX(PrjSch!$Z:$Z,MATCH(BF$9,PrjSch!$I:$I,0)) | BG21: =INDEX(PrjSch!$Z:$Z,MATCH(BG$9,PrjSch!$I:$I,0)) | BH21: =INDEX(PrjSch!$Z:$Z,MATCH(BH$9,PrjSch!$I:$I,0)) | DS21: Drive program concerns | DT21: D009
B22: P4 | C22: EC | D22: P4-03 | E22: Pre-Commissioning | F22: 0 | G22: 0 | H22: 0 | I22: 0 | J22: 0 | Y22: Supervisor | AO22: Stored | AP22: 12 | AQ22: Installation | AR22: Installation | AS22: =IF(PRODUCT(AT22:CN22)=1,1,0) | BI22: =INDEX(PrjSch!$Z:$Z,MATCH(BI$9,PrjSch!$I:$I,0)) | DS22: Product limitation | DT22: D010
B23: P5 | C23: EC | D23: P5-01 | E23: Commissioning | F23: 0 | G23: 0 | H23: 0 | I23: 0 | J23: 0 | Y23: Supervisor | AO23: Hold | AP23: 13 | AQ23: PreComm | AR23: PreComm | AS23: =IF(PRODUCT(AT23:CN23)=1,1,0) | BJ23: =INDEX(PrjSch!$Z:$Z,MATCH(BJ$9,PrjSch!$I:$I,0)) | DS23: Damaged Material | DT23: S005
B24: P5 | C24: EC | D24: P5-02 | E24: Final MOM/Site Report | F24: 0 | G24: 0 | H24: 0 | I24: 0 | J24: 0 | Y24: Supervisor | AO24: Cancelled | AP24: 14 | AQ24: Comm | AR24: Comm | AS24: =IF(PRODUCT(AT24:CN24)=1,1,0) | BK24: =INDEX(PrjSch!$Z:$Z,MATCH(BK$9,PrjSch!$I:$I,0)) | BL24: =INDEX(PrjSch!$Z:$Z,MATCH(BL$9,PrjSch!$I:$I,0)) | DS24: Wrong drilling/tapping | DT24: E004
B25: P5 | C25: SW | D25: P5-03 | E25: As Comm. Doc (SW) | F25: 2 | G25: 4 | H25: 8 | I25: 10 | J25: 12 | Y25: Fitter | AO25: Closed | AP25: 15 | AQ25: As-CommDoc | AR25: As-CommDoc | AS25: =IF(PRODUCT(AT25:CN25)=1,1,0) | BM25: =INDEX(PrjSch!$Z:$Z,MATCH(BM$9,PrjSch!$I:$I,0)) | DS25: Wrong cutout | DT25: E005
B26: P5 | C26: EC | D26: P5-03 | E26: Post Comm. Support | F26: 0 | G26: 0 | H26: 1 | I26: 0 | J26: 0 | Y26: Engineer | AP26: 16 | AQ26: PostCommSup | AR26: PostCommSup | AS26: =IF(PRODUCT(AT26:CN26)=1,1,0) | BN26: =INDEX(PrjSch!$Z:$Z,MATCH(BN$9,PrjSch!$I:$I,0)) | DS26: Dispatch Delayed | DT26: D011
B27: P5 | C27: SW | D27: P5-03 | E27: Project Closure | F27: 0 | G27: 0 | H27: 0 | I27: 1 | J27: 1 | Y27: Supervisor | AP27: 17 | AQ27: Closed | AR27: Closed | AS27: =IF(PRODUCT(AT27:CN27)=1,1,0) | BO27: =INDEX(PrjSch!$Z:$Z,MATCH(BO$9,PrjSch!$I:$I,0)) | DS27: Third party inspection | DT27: D012
Y28: Supervisor | AP28: 18 | DS28: Extended iFAT | DT28: D013
Y29: Fitter | DS29: Extended cFAT | DT29: D014
Y30: Supervisor
Y31: Supervisor
AM49: 90
AM50: 60
AM51: =AM49/AM50
E54: Critical Material Lead time
E55: Normal Material Lead time
